2023-10-05 11:24:19.929373  id: 11903  Excepcion: 'datos' 
2023-10-05 11:24:22.621096  id: 11033  Excepcion: 'datetime' 
2023-10-05 11:24:25.303393  id: 11032  Excepcion: 'datetime' 
2023-10-05 11:24:27.970853  id: 11034  Excepcion: 'datetime' 
2023-10-05 11:28:19.145572  id: 11903  Excepcion: 'datos' 
2023-10-05 12:57:33.660952  id: 11903  Excepcion: 'datos' 
2023-10-05 13:10:45.250701  id: 14901  Excepcion: 'datos' 
2023-10-05 13:11:03.777803  id: 14902  Excepcion: 'datos' 
2023-10-05 13:45:27.965708  id: 18077  Excepcion: 'datos' 
2023-10-05 13:49:35.065892  id: 18916  Excepcion: 'datos' 
2023-10-05 14:12:53.670795  id: 21902  Excepcion: 'datos' 
2023-10-05 14:53:02.303909  id: 26091  Excepcion: HTTPSConnectionPool(host='opendata.aemet.es', port=443): Max retries exceeded with url: /opendata/api/prediccion/especifica/municipio/diaria/26091 (Caused by NewConnectionError('<urllib3.connection.HTTPSConnection object at 0x000002731F1FFE20>: Failed to establish a new connection: [Errno 11001] getaddrinfo failed')) 
2023-10-05 15:39:11.928067  id: 26100  Excepcion: HTTPSConnectionPool(host='opendata.aemet.es', port=443): Max retries exceeded with url: /opendata/sh/5d59ef55 (Caused by NewConnectionError('<urllib3.connection.HTTPSConnection object at 0x000002731F1FE5F0>: Failed to establish a new connection: [Errno 11001] getaddrinfo failed')) 
2023-10-05 15:39:14.438161  id: 26101  Excepcion: HTTPSConnectionPool(host='opendata.aemet.es', port=443): Max retries exceeded with url: /opendata/api/prediccion/especifica/municipio/diaria/26101 (Caused by NewConnectionError('<urllib3.connection.HTTPSConnection object at 0x000002731F1FEE30>: Failed to establish a new connection: [Errno 11001] getaddrinfo failed')) 
2023-10-05 15:39:16.948221  id: 26102  Excepcion: HTTPSConnectionPool(host='opendata.aemet.es', port=443): Max retries exceeded with url: /opendata/api/prediccion/especifica/municipio/diaria/26102 (Caused by NewConnectionError('<urllib3.connection.HTTPSConnection object at 0x000002731F1FEF20>: Failed to establish a new connection: [Errno 11001] getaddrinfo failed')) 
2023-10-05 15:39:19.463599  id: 26103  Excepcion: HTTPSConnectionPool(host='opendata.aemet.es', port=443): Max retries exceeded with url: /opendata/api/prediccion/especifica/municipio/diaria/26103 (Caused by NewConnectionError('<urllib3.connection.HTTPSConnection object at 0x000002731F1FEC20>: Failed to establish a new connection: [Errno 11001] getaddrinfo failed')) 
2023-10-05 15:39:21.970574  id: 26104  Excepcion: HTTPSConnectionPool(host='opendata.aemet.es', port=443): Max retries exceeded with url: /opendata/api/prediccion/especifica/municipio/diaria/26104 (Caused by NewConnectionError('<urllib3.connection.HTTPSConnection object at 0x000002731F1FEF20>: Failed to establish a new connection: [Errno 11001] getaddrinfo failed')) 
2023-10-05 15:39:24.471605  id: 26105  Excepcion: HTTPSConnectionPool(host='opendata.aemet.es', port=443): Max retries exceeded with url: /opendata/api/prediccion/especifica/municipio/diaria/26105 (Caused by NewConnectionError('<urllib3.connection.HTTPSConnection object at 0x000002731F1FEC20>: Failed to establish a new connection: [Errno 11001] getaddrinfo failed')) 
2023-10-05 15:39:26.977294  id: 26106  Excepcion: HTTPSConnectionPool(host='opendata.aemet.es', port=443): Max retries exceeded with url: /opendata/api/prediccion/especifica/municipio/diaria/26106 (Caused by NewConnectionError('<urllib3.connection.HTTPSConnection object at 0x000002731F1FEF20>: Failed to establish a new connection: [Errno 11001] getaddrinfo failed')) 
2023-10-05 15:39:29.486491  id: 26107  Excepcion: HTTPSConnectionPool(host='opendata.aemet.es', port=443): Max retries exceeded with url: /opendata/api/prediccion/especifica/municipio/diaria/26107 (Caused by NewConnectionError('<urllib3.connection.HTTPSConnection object at 0x000002731F1FEC20>: Failed to establish a new connection: [Errno 11001] getaddrinfo failed')) 
2023-10-05 15:39:31.999341  id: 26109  Excepcion: HTTPSConnectionPool(host='opendata.aemet.es', port=443): Max retries exceeded with url: /opendata/api/prediccion/especifica/municipio/diaria/26109 (Caused by NewConnectionError('<urllib3.connection.HTTPSConnection object at 0x000002731F1FEF20>: Failed to establish a new connection: [Errno 11001] getaddrinfo failed')) 
2023-10-05 17:16:56.186736  id: 41904  Excepcion: 'datos' 
2023-10-05 19:18:04.596043  id: 46122  Excepcion: HTTPSConnectionPool(host='opendata.aemet.es', port=443): Max retries exceeded with url: /opendata/api/prediccion/especifica/municipio/diaria/46122 (Caused by NewConnectionError('<urllib3.connection.HTTPSConnection object at 0x000002731F1FFA00>: Failed to establish a new connection: [Errno 11001] getaddrinfo failed')) 
2023-10-06 13:41:37.154706  id: 46123  Excepcion: HTTPSConnectionPool(host='opendata.aemet.es', port=443): Max retries exceeded with url: /opendata/api/prediccion/especifica/municipio/diaria/46123 (Caused by NewConnectionError('<urllib3.connection.HTTPSConnection object at 0x000002731F1FD2A0>: Failed to establish a new connection: [Errno 11001] getaddrinfo failed')) 
2023-10-06 13:41:42.693182  id: 46126  Excepcion: HTTPSConnectionPool(host='opendata.aemet.es', port=443): Max retries exceeded with url: /opendata/api/prediccion/especifica/municipio/diaria/46126 (Caused by NewConnectionError('<urllib3.connection.HTTPSConnection object at 0x000002731F1FF5E0>: Failed to establish a new connection: [Errno 11001] getaddrinfo failed')) 
2023-10-06 13:41:45.199942  id: 46128  Excepcion: HTTPSConnectionPool(host='opendata.aemet.es', port=443): Max retries exceeded with url: /opendata/api/prediccion/especifica/municipio/diaria/46128 (Caused by NewConnectionError('<urllib3.connection.HTTPSConnection object at 0x000002731F1FD2A0>: Failed to establish a new connection: [Errno 11001] getaddrinfo failed')) 
2023-10-06 13:41:47.703822  id: 46127  Excepcion: HTTPSConnectionPool(host='opendata.aemet.es', port=443): Max retries exceeded with url: /opendata/api/prediccion/especifica/municipio/diaria/46127 (Caused by NewConnectionError('<urllib3.connection.HTTPSConnection object at 0x000002731F1FF5E0>: Failed to establish a new connection: [Errno 11001] getaddrinfo failed')) 
2023-10-06 13:41:50.215610  id: 46124  Excepcion: HTTPSConnectionPool(host='opendata.aemet.es', port=443): Max retries exceeded with url: /opendata/api/prediccion/especifica/municipio/diaria/46124 (Caused by NewConnectionError('<urllib3.connection.HTTPSConnection object at 0x000002731F1FD2A0>: Failed to establish a new connection: [Errno 11001] getaddrinfo failed')) 
2023-10-06 13:41:52.739890  id: 46125  Excepcion: HTTPSConnectionPool(host='opendata.aemet.es', port=443): Max retries exceeded with url: /opendata/api/prediccion/especifica/municipio/diaria/46125 (Caused by NewConnectionError('<urllib3.connection.HTTPSConnection object at 0x000002731F1FF8E0>: Failed to establish a new connection: [Errno 11001] getaddrinfo failed')) 
2023-10-06 14:00:34.963588  id: 4811  Excepcion: 'datos' 
